Workbook

Sheet Methodology Overview
A1: THE Interdisciplinary Rankings — Inputs Pillar (19%) → Research Funding (8%)
A2: Measures Financial Resources Available for Cross-Disciplinary Research | 8% of Total Ranking Score
A4: # | B4: Sub-Indicator | C4: Description & Measurement | D4: Approx. Weight
A5: 1 | B5: Total Research Income (Normalized) | C5: Total externally and internally sourced research funding received by the institution, normalized by number of academic staff (FTE). Includes government grants, industry-sponsored research, international funding, endowment-funded research, and institutional research allocations. Expressed as research income per academic FTE. | D5: ~3%
A6: 2 | B6: Interdisciplinary Research Funding (Proportion) | C6: Proportion of total research funding explicitly allocated to projects spanning 2+ departments or 2+ ASJC subject areas. Includes internal seed grants for cross-domain proposals, government mission-mode grants (SPARC, IMPRINT, DST), industry cross-domain R&D, and international collaborative grants. Higher proportion = stronger interdisciplinary investment. | D6: ~2%
A7: 3 | B7: Competitive Grant Success Rate | C7: Success rate of interdisciplinary grant proposals submitted to external competitive funding agencies (DST, DBT, SERB, ICMR, NSF, ERC, Horizon Europe, etc.). Calculated as: grants awarded ÷ proposals submitted × 100. Higher rates indicate research competitiveness and proposal quality. | D7: ~1.5%
A8: 4 | B8: Research Funding Diversity | C8: Measures how diversified an institution's research funding sources are (entropy on funding source distribution). Institutions reliant on a single funder score lower than those with balanced portfolios across government, industry, international, philanthropy, and internal sources. | D8: ~1%
A9: 5 | B9: Research Funding Sustainability & Growth | C9: Year-on-year growth rate of research funding over a 5-year window. Measures financial trajectory and institutional commitment to growing the research base. Includes assessment of multi-year grant pipelines and endowment contributions to research. | D9: ~0.5%
A11: Key Reference Notes
A12: • Research Funding contributes 8% to total ranking — the largest component of the Inputs pillar (19%).
A13: • Inputs pillar (19%) = Research Funding (8%) + Institutional Resources (6%) + Staff Quality (5%).
A14: • Data sources: institutional finance records, grant databases (DST/SERB/DBT/CSIR), audited accounts, THE submission.
A15: • Normalization by academic FTE ensures fair comparison between large and small institutions.
A16: • Interdisciplinary funding is identified by project scope spanning 2+ departments/ASJC areas in grant documentation.
A17: • Funding diversity uses Shannon entropy: H = −Σ pᵢ × log₂(pᵢ) on proportions across funding source categories.
A18: • 5-year growth rate: CAGR = (Year5/Year1)^(1/4) − 1, capturing compound annual growth.
A19: • Currency normalization: all funding figures converted to USD using PPP (Purchasing Power Parity) for global comparability.

Sheet 1. Total Research Income
A1: Total Research Income — All Sources (5-Year Window)
A2: Research funding received from all sources | Normalized by academic staff FTE | PPP-adjusted
A3: S.No. | B3: University Name | C3: Country | D3: Year 1 Funding (INR Cr / USD M) | E3: Year 2 Funding | F3: Year 3 Funding | G3: Year 4 Funding | H3: Year 5 Funding | I3: 5-Year Total Funding | J3: Academic Staff (FTE) | K3: Funding per FTE (INR L / USD K)
A4: 1 | I4: =SUM(D4:H4) -> 0 | K4: =IF(J4>0,I4/J4,0) -> 0
A5: 2 | I5: =SUM(D5:H5) -> 0 | K5: =IF(J5>0,I5/J5,0) -> 0
A6: 3 | I6: =SUM(D6:H6) -> 0 | K6: =IF(J6>0,I6/J6,0) -> 0
A7: 4 | I7: =SUM(D7:H7) -> 0 | K7: =IF(J7>0,I7/J7,0) -> 0
A8: 5 | I8: =SUM(D8:H8) -> 0 | K8: =IF(J8>0,I8/J8,0) -> 0
A9: 6 | I9: =SUM(D9:H9) -> 0 | K9: =IF(J9>0,I9/J9,0) -> 0
A10: 7 | I10: =SUM(D10:H10) -> 0 | K10: =IF(J10>0,I10/J10,0) -> 0
A11: 8 | I11: =SUM(D11:H11) -> 0 | K11: =IF(J11>0,I11/J11,0) -> 0
A12: 9 | I12: =SUM(D12:H12) -> 0 | K12: =IF(J12>0,I12/J12,0) -> 0
A13: 10 | I13: =SUM(D13:H13) -> 0 | K13: =IF(J13>0,I13/J13,0) -> 0
A14: 11 | I14: =SUM(D14:H14) -> 0 | K14: =IF(J14>0,I14/J14,0) -> 0
A15: 12 | I15: =SUM(D15:H15) -> 0 | K15: =IF(J15>0,I15/J15,0) -> 0
... A33: 30 | I33: =SUM(D33:H33) -> 0 | K33: =IF(J33>0,I33/J33,0) -> 0
A35: Summary Statistics
A36: Total Funding (All Universities) | F36: =SUM(I4:I33) -> 0
A37: Average 5-Year Funding | F37: =IF(COUNTA(I4:I33)>0,AVERAGE(I4:I33),0) -> 0
A38: Average Funding per FTE | F38: =IF(COUNTA(K4:K33)>0,AVERAGE(K4:K33),0) -> 0
A39: Highest Funding per FTE | F39: =MAX(K4:K33) -> 0
A40: Lowest Funding per FTE | F40: =MIN(K4:K33) -> 0

Sheet 2. Funding by Source
A1: Research Funding Breakdown by Source (5-Year Aggregate)
A2: Government | Industry | International | Philanthropy | Internal | Other — for funding diversity analysis
A3: S.No. | B3: University Name | C3: Country | D3: Government Grants (INR Cr / USD M) | E3: Industry Sponsored R&D | F3: International Grants / Collaborations | G3: Philanthropy / Endowment / CSR | H3: Internal / Institutional Allocation | I3: Other Sources | J3: Total (Auto-Sum) | K3: Reporting Period
A4: 1 | J4: =SUM(D4:I4) -> 0
A5: 2 | J5: =SUM(D5:I5) -> 0
A6: 3 | J6: =SUM(D6:I6) -> 0
A7: 4 | J7: =SUM(D7:I7) -> 0
A8: 5 | J8: =SUM(D8:I8) -> 0
A9: 6 | J9: =SUM(D9:I9) -> 0
A10: 7 | J10: =SUM(D10:I10) -> 0
A11: 8 | J11: =SUM(D11:I11) -> 0
A12: 9 | J12: =SUM(D12:I12) -> 0
A13: 10 | J13: =SUM(D13:I13) -> 0
A14: 11 | J14: =SUM(D14:I14) -> 0
A15: 12 | J15: =SUM(D15:I15) -> 0
... A33: 30 | J33: =SUM(D33:I33) -> 0
A35: Funding Source Proportions (%) — For Entropy Calculation
A36: S.No. | B36: University Name | C36: Country | D36: % Government | E36: % Industry | F36: % International | G36: % Philanthropy | H36: % Internal | I36: % Other | J36: Total % | K36: Funding Diversity Entropy (H)
A37: 1 | D37: =IFERROR(D4/$J$4*100,0) -> 0 | E37: =IFERROR(E4/$J$4*100,0) -> 0 | F37: =IFERROR(F4/$J$4*100,0) -> 0 | G37: =IFERROR(G4/$J$4*100,0) -> 0 | H37: =IFERROR(H4/$J$4*100,0) -> 0 | I37: =IFERROR(I4/$J$4*100,0) -> 0 | J37: =SUM(D37:I37) -> 0 | K37: =IFERROR(-SUMPRODUCT(IF(D37:I37>0,(D37:I37/100)*LOG(D37:I37/100,2),0)),0) -> 0
A38: 2 | D38: =IFERROR(D5/$J$5*100,0) -> 0 | E38: =IFERROR(E5/$J$5*100,0) -> 0 | F38: =IFERROR(F5/$J$5*100,0) -> 0 | G38: =IFERROR(G5/$J$5*100,0) -> 0 | H38: =IFERROR(H5/$J$5*100,0) -> 0 | I38: =IFERROR(I5/$J$5*100,0) -> 0 | J38: =SUM(D38:I38) -> 0 | K38: =IFERROR(-SUMPRODUCT(IF(D38:I38>0,(D38:I38/100)*LOG(D38:I38/100,2),0)),0) -> 0
A39: 3 | D39: =IFERROR(D6/$J$6*100,0) -> 0 | E39: =IFERROR(E6/$J$6*100,0) -> 0 | F39: =IFERROR(F6/$J$6*100,0) -> 0 | G39: =IFERROR(G6/$J$6*100,0) -> 0 | H39: =IFERROR(H6/$J$6*100,0) -> 0 | I39: =IFERROR(I6/$J$6*100,0) -> 0 | J39: =SUM(D39:I39) -> 0 | K39: =IFERROR(-SUMPRODUCT(IF(D39:I39>0,(D39:I39/100)*LOG(D39:I39/100,2),0)),0) -> 0
A40: 4 | D40: =IFERROR(D7/$J$7*100,0) -> 0 | E40: =IFERROR(E7/$J$7*100,0) -> 0 | F40: =IFERROR(F7/$J$7*100,0) -> 0 | G40: =IFERROR(G7/$J$7*100,0) -> 0 | H40: =IFERROR(H7/$J$7*100,0) -> 0 | I40: =IFERROR(I7/$J$7*100,0) -> 0 | J40: =SUM(D40:I40) -> 0 | K40: =IFERROR(-SUMPRODUCT(IF(D40:I40>0,(D40:I40/100)*LOG(D40:I40/100,2),0)),0) -> 0
A41: 5 | D41: =IFERROR(D8/$J$8*100,0) -> 0 | E41: =IFERROR(E8/$J$8*100,0) -> 0 | F41: =IFERROR(F8/$J$8*100,0) -> 0 | G41: =IFERROR(G8/$J$8*100,0) -> 0 | H41: =IFERROR(H8/$J$8*100,0) -> 0 | I41: =IFERROR(I8/$J$8*100,0) -> 0 | J41: =SUM(D41:I41) -> 0 | K41: =IFERROR(-SUMPRODUCT(IF(D41:I41>0,(D41:I41/100)*LOG(D41:I41/100,2),0)),0) -> 0
A42: 6 | D42: =IFERROR(D9/$J$9*100,0) -> 0 | E42: =IFERROR(E9/$J$9*100,0) -> 0 | F42: =IFERROR(F9/$J$9*100,0) -> 0 | G42: =IFERROR(G9/$J$9*100,0) -> 0 | H42: =IFERROR(H9/$J$9*100,0) -> 0 | I42: =IFERROR(I9/$J$9*100,0) -> 0 | J42: =SUM(D42:I42) -> 0 | K42: =IFERROR(-SUMPRODUCT(IF(D42:I42>0,(D42:I42/100)*LOG(D42:I42/100,2),0)),0) -> 0
A43: 7 | D43: =IFERROR(D10/$J$10*100,0) -> 0 | E43: =IFERROR(E10/$J$10*100,0) -> 0 | F43: =IFERROR(F10/$J$10*100,0) -> 0 | G43: =IFERROR(G10/$J$10*100,0) -> 0 | H43: =IFERROR(H10/$J$10*100,0) -> 0 | I43: =IFERROR(I10/$J$10*100,0) -> 0 | J43: =SUM(D43:I43) -> 0 | K43: =IFERROR(-SUMPRODUCT(IF(D43:I43>0,(D43:I43/100)*LOG(D43:I43/100,2),0)),0) -> 0
A44: 8 | D44: =IFERROR(D11/$J$11*100,0) -> 0 | E44: =IFERROR(E11/$J$11*100,0) -> 0 | F44: =IFERROR(F11/$J$11*100,0) -> 0 | G44: =IFERROR(G11/$J$11*100,0) -> 0 | H44: =IFERROR(H11/$J$11*100,0) -> 0 | I44: =IFERROR(I11/$J$11*100,0) -> 0 | J44: =SUM(D44:I44) -> 0 | K44: =IFERROR(-SUMPRODUCT(IF(D44:I44>0,(D44:I44/100)*LOG(D44:I44/100,2),0)),0) -> 0
A45: 9 | D45: =IFERROR(D12/$J$12*100,0) -> 0 | E45: =IFERROR(E12/$J$12*100,0) -> 0 | F45: =IFERROR(F12/$J$12*100,0) -> 0 | G45: =IFERROR(G12/$J$12*100,0) -> 0 | H45: =IFERROR(H12/$J$12*100,0) -> 0 | I45: =IFERROR(I12/$J$12*100,0) -> 0 | J45: =SUM(D45:I45) -> 0 | K45: =IFERROR(-SUMPRODUCT(IF(D45:I45>0,(D45:I45/100)*LOG(D45:I45/100,2),0)),0) -> 0
A46: 10 | D46: =IFERROR(D13/$J$13*100,0) -> 0 | E46: =IFERROR(E13/$J$13*100,0) -> 0 | F46: =IFERROR(F13/$J$13*100,0) -> 0 | G46: =IFERROR(G13/$J$13*100,0) -> 0 | H46: =IFERROR(H13/$J$13*100,0) -> 0 | I46: =IFERROR(I13/$J$13*100,0) -> 0 | J46: =SUM(D46:I46) -> 0 | K46: =IFERROR(-SUMPRODUCT(IF(D46:I46>0,(D46:I46/100)*LOG(D46:I46/100,2),0)),0) -> 0
A47: 11 | D47: =IFERROR(D14/$J$14*100,0) -> 0 | E47: =IFERROR(E14/$J$14*100,0) -> 0 | F47: =IFERROR(F14/$J$14*100,0) -> 0 | G47: =IFERROR(G14/$J$14*100,0) -> 0 | H47: =IFERROR(H14/$J$14*100,0) -> 0 | I47: =IFERROR(I14/$J$14*100,0) -> 0 | J47: =SUM(D47:I47) -> 0 | K47: =IFERROR(-SUMPRODUCT(IF(D47:I47>0,(D47:I47/100)*LOG(D47:I47/100,2),0)),0) -> 0
A48: 12 | D48: =IFERROR(D15/$J$15*100,0) -> 0 | E48: =IFERROR(E15/$J$15*100,0) -> 0 | F48: =IFERROR(F15/$J$15*100,0) -> 0 | G48: =IFERROR(G15/$J$15*100,0) -> 0 | H48: =IFERROR(H15/$J$15*100,0) -> 0 | I48: =IFERROR(I15/$J$15*100,0) -> 0 | J48: =SUM(D48:I48) -> 0 | K48: =IFERROR(-SUMPRODUCT(IF(D48:I48>0,(D48:I48/100)*LOG(D48:I48/100,2),0)),0) -> 0
A49: 13 | D49: =IFERROR(D16/$J$16*100,0) -> 0 | E49: =IFERROR(E16/$J$16*100,0) -> 0 | F49: =IFERROR(F16/$J$16*100,0) -> 0 | G49: =IFERROR(G16/$J$16*100,0) -> 0 | H49: =IFERROR(H16/$J$16*100,0) -> 0 | I49: =IFERROR(I16/$J$16*100,0) -> 0 | J49: =SUM(D49:I49) -> 0 | K49: =IFERROR(-SUMPRODUCT(IF(D49:I49>0,(D49:I49/100)*LOG(D49:I49/100,2),0)),0) -> 0
A50: 14 | D50: =IFERROR(D17/$J$17*100,0) -> 0 | E50: =IFERROR(E17/$J$17*100,0) -> 0 | F50: =IFERROR(F17/$J$17*100,0) -> 0 | G50: =IFERROR(G17/$J$17*100,0) -> 0 | H50: =IFERROR(H17/$J$17*100,0) -> 0 | I50: =IFERROR(I17/$J$17*100,0) -> 0 | J50: =SUM(D50:I50) -> 0 | K50: =IFERROR(-SUMPRODUCT(IF(D50:I50>0,(D50:I50/100)*LOG(D50:I50/100,2),0)),0) -> 0
A51: 15 | D51: =IFERROR(D18/$J$18*100,0) -> 0 | E51: =IFERROR(E18/$J$18*100,0) -> 0 | F51: =IFERROR(F18/$J$18*100,0) -> 0 | G51: =IFERROR(G18/$J$18*100,0) -> 0 | H51: =IFERROR(H18/$J$18*100,0) -> 0 | I51: =IFERROR(I18/$J$18*100,0) -> 0 | J51: =SUM(D51:I51) -> 0 | K51: =IFERROR(-SUMPRODUCT(IF(D51:I51>0,(D51:I51/100)*LOG(D51:I51/100,2),0)),0) -> 0
A52: 16 | D52: =IFERROR(D19/$J$19*100,0) -> 0 | E52: =IFERROR(E19/$J$19*100,0) -> 0 | F52: =IFERROR(F19/$J$19*100,0) -> 0 | G52: =IFERROR(G19/$J$19*100,0) -> 0 | H52: =IFERROR(H19/$J$19*100,0) -> 0 | I52: =IFERROR(I19/$J$19*100,0) -> 0 | J52: =SUM(D52:I52) -> 0 | K52: =IFERROR(-SUMPRODUCT(IF(D52:I52>0,(D52:I52/100)*LOG(D52:I52/100,2),0)),0) -> 0
A53: 17 | D53: =IFERROR(D20/$J$20*100,0) -> 0 | E53: =IFERROR(E20/$J$20*100,0) -> 0 | F53: =IFERROR(F20/$J$20*100,0) -> 0 | G53: =IFERROR(G20/$J$20*100,0) -> 0 | H53: =IFERROR(H20/$J$20*100,0) -> 0 | I53: =IFERROR(I20/$J$20*100,0) -> 0 | J53: =SUM(D53:I53) -> 0 | K53: =IFERROR(-SUMPRODUCT(IF(D53:I53>0,(D53:I53/100)*LOG(D53:I53/100,2),0)),0) -> 0
A54: 18 | D54: =IFERROR(D21/$J$21*100,0) -> 0 | E54: =IFERROR(E21/$J$21*100,0) -> 0 | F54: =IFERROR(F21/$J$21*100,0) -> 0 | G54: =IFERROR(G21/$J$21*100,0) -> 0 | H54: =IFERROR(H21/$J$21*100,0) -> 0 | I54: =IFERROR(I21/$J$21*100,0) -> 0 | J54: =SUM(D54:I54) -> 0 | K54: =IFERROR(-SUMPRODUCT(IF(D54:I54>0,(D54:I54/100)*LOG(D54:I54/100,2),0)),0) -> 0
A55: 19 | D55: =IFERROR(D22/$J$22*100,0) -> 0 | E55: =IFERROR(E22/$J$22*100,0) -> 0 | F55: =IFERROR(F22/$J$22*100,0) -> 0 | G55: =IFERROR(G22/$J$22*100,0) -> 0 | H55: =IFERROR(H22/$J$22*100,0) -> 0 | I55: =IFERROR(I22/$J$22*100,0) -> 0 | J55: =SUM(D55:I55) -> 0 | K55: =IFERROR(-SUMPRODUCT(IF(D55:I55>0,(D55:I55/100)*LOG(D55:I55/100,2),0)),0) -> 0
A56: 20 | D56: =IFERROR(D23/$J$23*100,0) -> 0 | E56: =IFERROR(E23/$J$23*100,0) -> 0 | F56: =IFERROR(F23/$J$23*100,0) -> 0 | G56: =IFERROR(G23/$J$23*100,0) -> 0 | H56: =IFERROR(H23/$J$23*100,0) -> 0 | I56: =IFERROR(I23/$J$23*100,0) -> 0 | J56: =SUM(D56:I56) -> 0 | K56: =IFERROR(-SUMPRODUCT(IF(D56:I56>0,(D56:I56/100)*LOG(D56:I56/100,2),0)),0) -> 0
A57: 21 | D57: =IFERROR(D24/$J$24*100,0) -> 0 | E57: =IFERROR(E24/$J$24*100,0) -> 0 | F57: =IFERROR(F24/$J$24*100,0) -> 0 | G57: =IFERROR(G24/$J$24*100,0) -> 0 | H57: =IFERROR(H24/$J$24*100,0) -> 0 | I57: =IFERROR(I24/$J$24*100,0) -> 0 | J57: =SUM(D57:I57) -> 0 | K57: =IFERROR(-SUMPRODUCT(IF(D57:I57>0,(D57:I57/100)*LOG(D57:I57/100,2),0)),0) -> 0
A58: 22 | D58: =IFERROR(D25/$J$25*100,0) -> 0 | E58: =IFERROR(E25/$J$25*100,0) -> 0 | F58: =IFERROR(F25/$J$25*100,0) -> 0 | G58: =IFERROR(G25/$J$25*100,0) -> 0 | H58: =IFERROR(H25/$J$25*100,0) -> 0 | I58: =IFERROR(I25/$J$25*100,0) -> 0 | J58: =SUM(D58:I58) -> 0 | K58: =IFERROR(-SUMPRODUCT(IF(D58:I58>0,(D58:I58/100)*LOG(D58:I58/100,2),0)),0) -> 0
...

Sheet 3. Interdisc. Funding
A1: Interdisciplinary Research Funding — Projects Spanning 2+ Departments / ASJC Areas
A2: Subset of total funding explicitly allocated to cross-domain research | Internal + External sources
A3: S.No. | B3: University Name | C3: Country | D3: Total Research Funding (5yr) | E3: Internal Interdisc. Seed Grants | F3: Govt Mission-Mode (SPARC/IMPRINT/DST) | G3: Industry Cross-Domain R&D | H3: International Interdisc. Grants | I3: Total Interdisc. Funding | J3: % Interdisc. of Total | K3: Reporting Period
A4: 1 | I4: =SUM(E4:H4) -> 0 | J4: =IF(D4>0,I4/D4*100,0) -> 0
A5: 2 | I5: =SUM(E5:H5) -> 0 | J5: =IF(D5>0,I5/D5*100,0) -> 0
A6: 3 | I6: =SUM(E6:H6) -> 0 | J6: =IF(D6>0,I6/D6*100,0) -> 0
A7: 4 | I7: =SUM(E7:H7) -> 0 | J7: =IF(D7>0,I7/D7*100,0) -> 0
A8: 5 | I8: =SUM(E8:H8) -> 0 | J8: =IF(D8>0,I8/D8*100,0) -> 0
A9: 6 | I9: =SUM(E9:H9) -> 0 | J9: =IF(D9>0,I9/D9*100,0) -> 0
A10: 7 | I10: =SUM(E10:H10) -> 0 | J10: =IF(D10>0,I10/D10*100,0) -> 0
A11: 8 | I11: =SUM(E11:H11) -> 0 | J11: =IF(D11>0,I11/D11*100,0) -> 0
A12: 9 | I12: =SUM(E12:H12) -> 0 | J12: =IF(D12>0,I12/D12*100,0) -> 0
A13: 10 | I13: =SUM(E13:H13) -> 0 | J13: =IF(D13>0,I13/D13*100,0) -> 0
A14: 11 | I14: =SUM(E14:H14) -> 0 | J14: =IF(D14>0,I14/D14*100,0) -> 0
A15: 12 | I15: =SUM(E15:H15) -> 0 | J15: =IF(D15>0,I15/D15*100,0) -> 0
... A33: 30 | I33: =SUM(E33:H33) -> 0 | J33: =IF(D33>0,I33/D33*100,0) -> 0
A35: Detailed Interdisciplinary Grant Log
A36: S.No. | B36: Grant / Project Title | C36: Funding Agency / Source | D36: Amount (INR L / USD K) | E36: Disciplines / ASJC Areas (list 2+) | F36: Departments Involved | G36: PI & Co-PI Names | H36: Duration (Years) | I36: Status (Active/Completed/Pipeline) | J36: Cross-Domain (Verified Y/N) | K36: University Name
A37: 1
A38: 2
A39: 3
A40: 4
A41: 5
A42: 6
A43: 7
A44: 8
A45: 9
A46: 10
A47: 11
A48: 12
... A86: 50

Sheet 4. Grant Success Rate
A1: Competitive Grant Success Rate — Interdisciplinary Proposals
A2: Success = grants awarded ÷ proposals submitted × 100 | Tracks competitiveness of cross-domain proposals
A3: S.No. | B3: University Name | C3: Country | D3: Total Proposals Submitted (5yr) | E3: Interdisc. Proposals Submitted | F3: Interdisc. Proposals Awarded | G3: Success Rate (Interdisc.) % | H3: Total Proposals Awarded (All) | I3: Overall Success Rate % | J3: Reporting Period
A4: 1 | G4: =IF(E4>0,F4/E4*100,0) -> 0 | I4: =IF(D4>0,H4/D4*100,0) -> 0
A5: 2 | G5: =IF(E5>0,F5/E5*100,0) -> 0 | I5: =IF(D5>0,H5/D5*100,0) -> 0
A6: 3 | G6: =IF(E6>0,F6/E6*100,0) -> 0 | I6: =IF(D6>0,H6/D6*100,0) -> 0
A7: 4 | G7: =IF(E7>0,F7/E7*100,0) -> 0 | I7: =IF(D7>0,H7/D7*100,0) -> 0
A8: 5 | G8: =IF(E8>0,F8/E8*100,0) -> 0 | I8: =IF(D8>0,H8/D8*100,0) -> 0
A9: 6 | G9: =IF(E9>0,F9/E9*100,0) -> 0 | I9: =IF(D9>0,H9/D9*100,0) -> 0
A10: 7 | G10: =IF(E10>0,F10/E10*100,0) -> 0 | I10: =IF(D10>0,H10/D10*100,0) -> 0
A11: 8 | G11: =IF(E11>0,F11/E11*100,0) -> 0 | I11: =IF(D11>0,H11/D11*100,0) -> 0
A12: 9 | G12: =IF(E12>0,F12/E12*100,0) -> 0 | I12: =IF(D12>0,H12/D12*100,0) -> 0
A13: 10 | G13: =IF(E13>0,F13/E13*100,0) -> 0 | I13: =IF(D13>0,H13/D13*100,0) -> 0
A14: 11 | G14: =IF(E14>0,F14/E14*100,0) -> 0 | I14: =IF(D14>0,H14/D14*100,0) -> 0
A15: 12 | G15: =IF(E15>0,F15/E15*100,0) -> 0 | I15: =IF(D15>0,H15/D15*100,0) -> 0
... A33: 30 | G33: =IF(E33>0,F33/E33*100,0) -> 0 | I33: =IF(D33>0,H33/D33*100,0) -> 0
A35: Success Rate by Funding Agency (Per University)
A36: S.No. | B36: Funding Agency | C36: Proposals Submitted | D36: Proposals Awarded | E36: Success Rate (%) | F36: Interdisc. Proposals Submitted | G36: Interdisc. Awarded | H36: Interdisc. Success Rate (%) | I36: Total Funding Won (INR L / USD K) | J36: University Name
A37: 1 | E37: =IF(C37>0,D37/C37*100,0) -> 0 | H37: =IF(F37>0,G37/F37*100,0) -> 0
A38: 2 | E38: =IF(C38>0,D38/C38*100,0) -> 0 | H38: =IF(F38>0,G38/F38*100,0) -> 0
A39: 3 | E39: =IF(C39>0,D39/C39*100,0) -> 0 | H39: =IF(F39>0,G39/F39*100,0) -> 0
A40: 4 | E40: =IF(C40>0,D40/C40*100,0) -> 0 | H40: =IF(F40>0,G40/F40*100,0) -> 0
A41: 5 | E41: =IF(C41>0,D41/C41*100,0) -> 0 | H41: =IF(F41>0,G41/F41*100,0) -> 0
A42: 6 | E42: =IF(C42>0,D42/C42*100,0) -> 0 | H42: =IF(F42>0,G42/F42*100,0) -> 0
A43: 7 | E43: =IF(C43>0,D43/C43*100,0) -> 0 | H43: =IF(F43>0,G43/F43*100,0) -> 0
A44: 8 | E44: =IF(C44>0,D44/C44*100,0) -> 0 | H44: =IF(F44>0,G44/F44*100,0) -> 0
A45: 9 | E45: =IF(C45>0,D45/C45*100,0) -> 0 | H45: =IF(F45>0,G45/F45*100,0) -> 0
A46: 10 | E46: =IF(C46>0,D46/C46*100,0) -> 0 | H46: =IF(F46>0,G46/F46*100,0) -> 0
A47: 11 | E47: =IF(C47>0,D47/C47*100,0) -> 0 | H47: =IF(F47>0,G47/F47*100,0) -> 0
A48: 12 | E48: =IF(C48>0,D48/C48*100,0) -> 0 | H48: =IF(F48>0,G48/F48*100,0) -> 0
... A66: 30 | E66: =IF(C66>0,D66/C66*100,0) -> 0 | H66: =IF(F66>0,G66/F66*100,0) -> 0

Sheet 5. Funding Diversity
A1: Research Funding Diversity — Shannon Entropy Analysis
A2: H = −Σ pᵢ × log₂(pᵢ) on funding source proportions | Higher H = more diversified funding base
A3: S.No. | B3: University Name | C3: Country | D3: No. of Active Funding Sources | E3: Entropy H (bits) | F3: Max Entropy log₂(N) | G3: Normalized Entropy (H/Hmax) | H3: Diversity Score (0–100) | I3: Diversity Tier
A4: 1 | E4: ='2. Funding by Source'!K37 -> 0 | F4: =IF(D4>1,LOG(D4,2),0) -> 0 | G4: =IFERROR(IF(F4>0,E4/F4,0),0) -> 0 | H4: =IFERROR(IF(MAX($E$4:$E$33)>0,E4/MAX($E$4:$E$33)*100,0),0) -> 0 | I4: =IF(H4>=80,"Very High",IF(H4>=60,"High",IF(H4>=40,"Medium",IF(H4>=20,"Low","Very Low")))) -> Very Low
A5: 2 | E5: ='2. Funding by Source'!K38 -> 0 | F5: =IF(D5>1,LOG(D5,2),0) -> 0 | G5: =IFERROR(IF(F5>0,E5/F5,0),0) -> 0 | H5: =IFERROR(IF(MAX($E$4:$E$33)>0,E5/MAX($E$4:$E$33)*100,0),0) -> 0 | I5: =IF(H5>=80,"Very High",IF(H5>=60,"High",IF(H5>=40,"Medium",IF(H5>=20,"Low","Very Low")))) -> Very Low
A6: 3 | E6: ='2. Funding by Source'!K39 -> 0 | F6: =IF(D6>1,LOG(D6,2),0) -> 0 | G6: =IFERROR(IF(F6>0,E6/F6,0),0) -> 0 | H6: =IFERROR(IF(MAX($E$4:$E$33)>0,E6/MAX($E$4:$E$33)*100,0),0) -> 0 | I6: =IF(H6>=80,"Very High",IF(H6>=60,"High",IF(H6>=40,"Medium",IF(H6>=20,"Low","Very Low")))) -> Very Low
A7: 4 | E7: ='2. Funding by Source'!K40 -> 0 | F7: =IF(D7>1,LOG(D7,2),0) -> 0 | G7: =IFERROR(IF(F7>0,E7/F7,0),0) -> 0 | H7: =IFERROR(IF(MAX($E$4:$E$33)>0,E7/MAX($E$4:$E$33)*100,0),0) -> 0 | I7: =IF(H7>=80,"Very High",IF(H7>=60,"High",IF(H7>=40,"Medium",IF(H7>=20,"Low","Very Low")))) -> Very Low
A8: 5 | E8: ='2. Funding by Source'!K41 -> 0 | F8: =IF(D8>1,LOG(D8,2),0) -> 0 | G8: =IFERROR(IF(F8>0,E8/F8,0),0) -> 0 | H8: =IFERROR(IF(MAX($E$4:$E$33)>0,E8/MAX($E$4:$E$33)*100,0),0) -> 0 | I8: =IF(H8>=80,"Very High",IF(H8>=60,"High",IF(H8>=40,"Medium",IF(H8>=20,"Low","Very Low")))) -> Very Low
A9: 6 | E9: ='2. Funding by Source'!K42 -> 0 | F9: =IF(D9>1,LOG(D9,2),0) -> 0 | G9: =IFERROR(IF(F9>0,E9/F9,0),0) -> 0 | H9: =IFERROR(IF(MAX($E$4:$E$33)>0,E9/MAX($E$4:$E$33)*100,0),0) -> 0 | I9: =IF(H9>=80,"Very High",IF(H9>=60,"High",IF(H9>=40,"Medium",IF(H9>=20,"Low","Very Low")))) -> Very Low
A10: 7 | E10: ='2. Funding by Source'!K43 -> 0 | F10: =IF(D10>1,LOG(D10,2),0) -> 0 | G10: =IFERROR(IF(F10>0,E10/F10,0),0) -> 0 | H10: =IFERROR(IF(MAX($E$4:$E$33)>0,E10/MAX($E$4:$E$33)*100,0),0) -> 0 | I10: =IF(H10>=80,"Very High",IF(H10>=60,"High",IF(H10>=40,"Medium",IF(H10>=20,"Low","Very Low")))) -> Very Low
A11: 8 | E11: ='2. Funding by Source'!K44 -> 0 | F11: =IF(D11>1,LOG(D11,2),0) -> 0 | G11: =IFERROR(IF(F11>0,E11/F11,0),0) -> 0 | H11: =IFERROR(IF(MAX($E$4:$E$33)>0,E11/MAX($E$4:$E$33)*100,0),0) -> 0 | I11: =IF(H11>=80,"Very High",IF(H11>=60,"High",IF(H11>=40,"Medium",IF(H11>=20,"Low","Very Low")))) -> Very Low
A12: 9 | E12: ='2. Funding by Source'!K45 -> 0 | F12: =IF(D12>1,LOG(D12,2),0) -> 0 | G12: =IFERROR(IF(F12>0,E12/F12,0),0) -> 0 | H12: =IFERROR(IF(MAX($E$4:$E$33)>0,E12/MAX($E$4:$E$33)*100,0),0) -> 0 | I12: =IF(H12>=80,"Very High",IF(H12>=60,"High",IF(H12>=40,"Medium",IF(H12>=20,"Low","Very Low")))) -> Very Low
A13: 10 | E13: ='2. Funding by Source'!K46 -> 0 | F13: =IF(D13>1,LOG(D13,2),0) -> 0 | G13: =IFERROR(IF(F13>0,E13/F13,0),0) -> 0 | H13: =IFERROR(IF(MAX($E$4:$E$33)>0,E13/MAX($E$4:$E$33)*100,0),0) -> 0 | I13: =IF(H13>=80,"Very High",IF(H13>=60,"High",IF(H13>=40,"Medium",IF(H13>=20,"Low","Very Low")))) -> Very Low
A14: 11 | E14: ='2. Funding by Source'!K47 -> 0 | F14: =IF(D14>1,LOG(D14,2),0) -> 0 | G14: =IFERROR(IF(F14>0,E14/F14,0),0) -> 0 | H14: =IFERROR(IF(MAX($E$4:$E$33)>0,E14/MAX($E$4:$E$33)*100,0),0) -> 0 | I14: =IF(H14>=80,"Very High",IF(H14>=60,"High",IF(H14>=40,"Medium",IF(H14>=20,"Low","Very Low")))) -> Very Low
A15: 12 | E15: ='2. Funding by Source'!K48 -> 0 | F15: =IF(D15>1,LOG(D15,2),0) -> 0 | G15: =IFERROR(IF(F15>0,E15/F15,0),0) -> 0 | H15: =IFERROR(IF(MAX($E$4:$E$33)>0,E15/MAX($E$4:$E$33)*100,0),0) -> 0 | I15: =IF(H15>=80,"Very High",IF(H15>=60,"High",IF(H15>=40,"Medium",IF(H15>=20,"Low","Very Low")))) -> Very Low
... A33: 30 | E33: ='2. Funding by Source'!K66 -> 0 | F33: =IF(D33>1,LOG(D33,2),0) -> 0 | G33: =IFERROR(IF(F33>0,E33/F33,0),0) -> 0 | H33: =IFERROR(IF(MAX($E$4:$E$33)>0,E33/MAX($E$4:$E$33)*100,0),0) -> 0 | I33: =IF(H33>=80,"Very High",IF(H33>=60,"High",IF(H33>=40,"Medium",IF(H33>=20,"Low","Very Low")))) -> Very Low

Sheet 6. Funding Growth
A1: Research Funding Sustainability & Growth (5-Year Trajectory)
A2: CAGR = (Year5/Year1)^(1/4) − 1 | Tracks compound annual growth of research funding
A3: S.No. | B3: University Name | C3: Country | D3: Year 1 Funding | E3: Year 2 Funding | F3: Year 3 Funding | G3: Year 4 Funding | H3: Year 5 Funding | I3: CAGR (%) | J3: 5-Year Absolute Growth (%) | K3: Growth Tier
A4: 1 | I4: =IFERROR(IF(AND(D4>0,H4>0),(H4/D4)^(1/4)-1,0)*100,0) -> 0 | J4: =IFERROR(IF(D4>0,(H4-D4)/D4*100,0),0) -> 0 | K4: =IF(I4>=15,"High Growth",IF(I4>=5,"Moderate Growth",IF(I4>=0,"Stable","Declining"))) -> Stable
A5: 2 | I5: =IFERROR(IF(AND(D5>0,H5>0),(H5/D5)^(1/4)-1,0)*100,0) -> 0 | J5: =IFERROR(IF(D5>0,(H5-D5)/D5*100,0),0) -> 0 | K5: =IF(I5>=15,"High Growth",IF(I5>=5,"Moderate Growth",IF(I5>=0,"Stable","Declining"))) -> Stable
A6: 3 | I6: =IFERROR(IF(AND(D6>0,H6>0),(H6/D6)^(1/4)-1,0)*100,0) -> 0 | J6: =IFERROR(IF(D6>0,(H6-D6)/D6*100,0),0) -> 0 | K6: =IF(I6>=15,"High Growth",IF(I6>=5,"Moderate Growth",IF(I6>=0,"Stable","Declining"))) -> Stable
A7: 4 | I7: =IFERROR(IF(AND(D7>0,H7>0),(H7/D7)^(1/4)-1,0)*100,0) -> 0 | J7: =IFERROR(IF(D7>0,(H7-D7)/D7*100,0),0) -> 0 | K7: =IF(I7>=15,"High Growth",IF(I7>=5,"Moderate Growth",IF(I7>=0,"Stable","Declining"))) -> Stable
A8: 5 | I8: =IFERROR(IF(AND(D8>0,H8>0),(H8/D8)^(1/4)-1,0)*100,0) -> 0 | J8: =IFERROR(IF(D8>0,(H8-D8)/D8*100,0),0) -> 0 | K8: =IF(I8>=15,"High Growth",IF(I8>=5,"Moderate Growth",IF(I8>=0,"Stable","Declining"))) -> Stable
A9: 6 | I9: =IFERROR(IF(AND(D9>0,H9>0),(H9/D9)^(1/4)-1,0)*100,0) -> 0 | J9: =IFERROR(IF(D9>0,(H9-D9)/D9*100,0),0) -> 0 | K9: =IF(I9>=15,"High Growth",IF(I9>=5,"Moderate Growth",IF(I9>=0,"Stable","Declining"))) -> Stable
A10: 7 | I10: =IFERROR(IF(AND(D10>0,H10>0),(H10/D10)^(1/4)-1,0)*100,0) -> 0 | J10: =IFERROR(IF(D10>0,(H10-D10)/D10*100,0),0) -> 0 | K10: =IF(I10>=15,"High Growth",IF(I10>=5,"Moderate Growth",IF(I10>=0,"Stable","Declining"))) -> Stable
A11: 8 | I11: =IFERROR(IF(AND(D11>0,H11>0),(H11/D11)^(1/4)-1,0)*100,0) -> 0 | J11: =IFERROR(IF(D11>0,(H11-D11)/D11*100,0),0) -> 0 | K11: =IF(I11>=15,"High Growth",IF(I11>=5,"Moderate Growth",IF(I11>=0,"Stable","Declining"))) -> Stable
A12: 9 | I12: =IFERROR(IF(AND(D12>0,H12>0),(H12/D12)^(1/4)-1,0)*100,0) -> 0 | J12: =IFERROR(IF(D12>0,(H12-D12)/D12*100,0),0) -> 0 | K12: =IF(I12>=15,"High Growth",IF(I12>=5,"Moderate Growth",IF(I12>=0,"Stable","Declining"))) -> Stable
A13: 10 | I13: =IFERROR(IF(AND(D13>0,H13>0),(H13/D13)^(1/4)-1,0)*100,0) -> 0 | J13: =IFERROR(IF(D13>0,(H13-D13)/D13*100,0),0) -> 0 | K13: =IF(I13>=15,"High Growth",IF(I13>=5,"Moderate Growth",IF(I13>=0,"Stable","Declining"))) -> Stable
A14: 11 | I14: =IFERROR(IF(AND(D14>0,H14>0),(H14/D14)^(1/4)-1,0)*100,0) -> 0 | J14: =IFERROR(IF(D14>0,(H14-D14)/D14*100,0),0) -> 0 | K14: =IF(I14>=15,"High Growth",IF(I14>=5,"Moderate Growth",IF(I14>=0,"Stable","Declining"))) -> Stable
A15: 12 | I15: =IFERROR(IF(AND(D15>0,H15>0),(H15/D15)^(1/4)-1,0)*100,0) -> 0 | J15: =IFERROR(IF(D15>0,(H15-D15)/D15*100,0),0) -> 0 | K15: =IF(I15>=15,"High Growth",IF(I15>=5,"Moderate Growth",IF(I15>=0,"Stable","Declining"))) -> Stable
... A33: 30 | I33: =IFERROR(IF(AND(D33>0,H33>0),(H33/D33)^(1/4)-1,0)*100,0) -> 0 | J33: =IFERROR(IF(D33>0,(H33-D33)/D33*100,0),0) -> 0 | K33: =IF(I33>=15,"High Growth",IF(I33>=5,"Moderate Growth",IF(I33>=0,"Stable","Declining"))) -> Stable

Sheet 7. Funding Agencies Ref
A1: Major Research Funding Agencies — Reference List
A2: Key national & international agencies funding interdisciplinary research
A3: # | B3: Country | C3: Agency Name | D3: Acronym | E3: Focus / Interdisciplinary Relevance | F3: Type
A4: 1 | B4: India | C4: Department of Science & Technology | D4: DST | E4: Funds SPARC, INSPIRE, mission-mode cross-domain research | F4: Government
A5: 2 | B5: India | C5: Science & Engineering Research Board | D5: SERB | E5: Competitive grants; CRG, MATRICS, POWER for multi-domain research | F5: Government
A6: 3 | B6: India | C6: Dept. of Biotechnology | D6: DBT | E6: Biotech-engineering-health convergence grants | F6: Government
A7: 4 | B7: India | C7: Indian Council of Medical Research | D7: ICMR | E7: Health research crossing into engineering, AI, data science | F7: Government
A8: 5 | B8: India | C8: CSIR | D8: CSIR | E8: Multi-lab, multi-domain national research programmes | F8: Government
A9: 6 | B9: India | C9: AICTE / MHRD (MoE) | D9: AICTE | E9: IMPRINT, SPARC for engineering + science convergence | F9: Government
A10: 7 | B10: USA | C10: National Science Foundation | D10: NSF | E10: Convergence Accelerator; cross-domain STEM grants | F10: Government
A11: 8 | B11: USA | C11: National Institutes of Health | D11: NIH | E11: Biomedical + data science + engineering convergence | F11: Government
A12: 9 | B12: EU | C12: European Research Council | D12: ERC | E12: Frontier interdisciplinary research grants | F12: Government
A13: 10 | B13: EU | C13: Horizon Europe | D13: HE | E13: Mission-driven cross-domain research funding | F13: Government
A14: 11 | B14: UK | C14: UK Research & Innovation | D14: UKRI | E14: Cross-council interdisciplinary research | F14: Government
A15: 12 | B15: Global | C15: World Bank / ADB | D15: WB/ADB | E15: Development research crossing multiple domains | F15: Multilateral
... A18: 15 | B18: Industry | C18: Various (Tata, Infosys, Google, etc.) | D18: — | E18: CSR + R&D funding for applied cross-domain research | F18: Industry

Sheet 8. Composite RF Score
A1: Composite Research Funding Score (0–100) — 8% of Total Ranking
A2: Weighted composite of 5 sub-indicators | Weights editable in Row 4
A3: S.No. | B3: University Name | C3: Total Income/FTE (A) | D3: Interdisc. Funding % (B) | E3: Grant Success Rate (C) | F3: Funding Diversity (D) | G3: Growth CAGR (E) | H3: Composite RF Score (0–100) | I3: Global Rank
B4: Weights → | C4: 0.375 | D4: 0.25 | E4: 0.1875 | F4: 0.125 | G4: 0.0625
A5: 1 | H5: =C5*$C$4+D5*$D$4+E5*$E$4+F5*$F$4+G5*$G$4 -> 0 | I5: =IFERROR(RANK(H5,$H$5:$H$34,0),"") -> 1
A6: 2 | H6: =C6*$C$4+D6*$D$4+E6*$E$4+F6*$F$4+G6*$G$4 -> 0 | I6: =IFERROR(RANK(H6,$H$5:$H$34,0),"") -> 1
A7: 3 | H7: =C7*$C$4+D7*$D$4+E7*$E$4+F7*$F$4+G7*$G$4 -> 0 | I7: =IFERROR(RANK(H7,$H$5:$H$34,0),"") -> 1
A8: 4 | H8: =C8*$C$4+D8*$D$4+E8*$E$4+F8*$F$4+G8*$G$4 -> 0 | I8: =IFERROR(RANK(H8,$H$5:$H$34,0),"") -> 1
A9: 5 | H9: =C9*$C$4+D9*$D$4+E9*$E$4+F9*$F$4+G9*$G$4 -> 0 | I9: =IFERROR(RANK(H9,$H$5:$H$34,0),"") -> 1
A10: 6 | H10: =C10*$C$4+D10*$D$4+E10*$E$4+F10*$F$4+G10*$G$4 -> 0 | I10: =IFERROR(RANK(H10,$H$5:$H$34,0),"") -> 1
A11: 7 | H11: =C11*$C$4+D11*$D$4+E11*$E$4+F11*$F$4+G11*$G$4 -> 0 | I11: =IFERROR(RANK(H11,$H$5:$H$34,0),"") -> 1
A12: 8 | H12: =C12*$C$4+D12*$D$4+E12*$E$4+F12*$F$4+G12*$G$4 -> 0 | I12: =IFERROR(RANK(H12,$H$5:$H$34,0),"") -> 1
A13: 9 | H13: =C13*$C$4+D13*$D$4+E13*$E$4+F13*$F$4+G13*$G$4 -> 0 | I13: =IFERROR(RANK(H13,$H$5:$H$34,0),"") -> 1
A14: 10 | H14: =C14*$C$4+D14*$D$4+E14*$E$4+F14*$F$4+G14*$G$4 -> 0 | I14: =IFERROR(RANK(H14,$H$5:$H$34,0),"") -> 1
A15: 11 | H15: =C15*$C$4+D15*$D$4+E15*$E$4+F15*$F$4+G15*$G$4 -> 0 | I15: =IFERROR(RANK(H15,$H$5:$H$34,0),"") -> 1
A16: 12 | H16: =C16*$C$4+D16*$D$4+E16*$E$4+F16*$F$4+G16*$G$4 -> 0 | I16: =IFERROR(RANK(H16,$H$5:$H$34,0),"") -> 1
... A34: 30 | H34: =C34*$C$4+D34*$D$4+E34*$E$4+F34*$F$4+G34*$G$4 -> 0 | I34: =IFERROR(RANK(H34,$H$5:$H$34,0),"") -> 1

Sheet 9. Benchmarking
A1: Benchmarking & Peer Comparison — Research Funding
A2: Compare your institution against peers, aspirational targets, and global top performers
A3: S.No. | B3: University / Benchmark | C3: Income/FTE | D3: % Interdisc. | E3: Success Rate | F3: Diversity | G3: Growth | H3: Composite RF | I3: Peer Group
A4: 1 | B4: Your Institution | I4: Target
A5: 2 | B5: Global Top 10 Average | I5: Aspirational
A6: 3 | B6: National Average | I6: National
A7: 4 | B7: Peer Group Average | I7: Peer
A8: 1
A9: 2
A10: 3
A11: 4
A12: 5
A13: 6
A14: 7
A15: 8
A16: 9
A17: 10
A18: 11
A19: 12
... A22: 15

Sheet 10. Data Quality Audit
A1: Research Funding — Data Quality & Audit Checklist
A2: Validation checks for all sub-indicators of the Research Funding component (8% of total ranking)
A3: # | B3: Quality Check | C3: Description | D3: Status (✓/✗/IP) | E3: Date | F3: Reviewer
A4: 1 | B4: Funding data source verification | C4: All figures verified against audited financial statements or grant database records
A5: 2 | B5: Currency & PPP normalization | C5: All funding figures converted to common currency (USD) using World Bank PPP rates for the relevant year
A6: 3 | B6: Academic FTE definition | C6: FTE calculated per THE guidelines (full-time equivalent academic staff excluding admin/support)
A7: 4 | B7: 5-year window consistency | C7: All 5 years of data cover the same fiscal/calendar year definition (Apr-Mar or Jan-Dec)
A8: 5 | B8: Interdisciplinary funding criteria | C8: Each grant classified as 'interdisciplinary' verified as spanning 2+ departments or ASJC areas in grant scope
A9: 6 | B9: Double-counting prevention | C9: Same funding not counted in multiple source categories (e.g., a DST grant counted only once)
A10: 7 | B10: Grant log completeness | C10: Detailed grant log includes all major interdisciplinary grants above threshold (e.g., INR 5L / USD 10K)
A11: 8 | B11: Success rate data integrity | C11: Proposals submitted and awarded counts verified against funding agency acknowledgement records
A12: 9 | B12: Funding source categorization | C12: All funding mapped to exactly one of 6 categories: Government, Industry, International, Philanthropy, Internal, Other
A13: 10 | B13: Entropy calculation validation | C13: Shannon entropy formula uses log₂ consistently; proportions sum to 100%; verified for 2–3 universities
A14: 11 | B14: CAGR formula verification | C14: CAGR = (Year5/Year1)^(1/4) − 1 verified; negative growth correctly handled
A15: 12 | B15: Inflation adjustment | C15: Nominal vs. real growth distinguished; growth rates ideally inflation-adjusted
... A23: 20 | B23: Reproducibility test | C23: All calculations reproducible by independent analyst using this workbook and financial records
